<?xml version="1.0" ?><testsuite errors="0" failures="24" hostname="localhost" name="lettuce" tests="171" time="0" timestamp="2013-10-21T12:34:44"><testcase classname="Logging Mechanism : Log the unica correlator received" name="Given the DB has no classes already published" time="0.017056"/><testcase classname="Logging Mechanism : Log the unica correlator received" name="When I send to $base_api_url/$apis_url the class data with unica_correlator example_of_correlator_32_chars__:" time="0.017795"><failure message="classes_url" type="KeyError"><![CDATA[Traceback (most recent call last):
  File "/Library/Frameworks/Python.framework/Versions/2.7/lib/python2.7/site-packages/lettuce/core.py", line 144, in __call__
    ret = self.function(self.step, *args, **kw)
  File "/Users/eag/workspace/tdaf-servicedirectory/test/acceptance/src/e2e/logs_and_alarms/logging_mechanism/steps.py", line 91, in i_send_to_url_the_class_data_with_unica_correlator
    api_utils.send_to_url_the_class_data(step, url, 0, {"Unica-Correlator" : correlator})
  File "/Users/eag/workspace/tdaf-servicedirectory/test/acceptance/src/e2e/common/api_utils.py", line 168, in send_to_url_the_class_data
    rest_utils.send_to_url_the_data(step, url, world.published_capability, header)
  File "/Users/eag/workspace/tdaf-servicedirectory/test/acceptance/src/e2e/common/rest_utils.py", line 82, in send_to_url_the_data
    url = self._get_url_with_values(url_template)
  File "/Users/eag/workspace/tdaf-servicedirectory/test/acceptance/src/e2e/common/rest_utils.py", line 365, in _get_url_with_values
    classes_url=world.config["django"]["classes_url"],
KeyError: 'classes_url'
]]></failure></testcase><testcase classname="Logging Mechanism : Log the unica correlator received" name="Then the format of the logs is correct" time="0.015879"><skipped type="UndefinedStep(Then the format of the logs is correct)"/></testcase><testcase classname="Logging Mechanism : Log the unica correlator received" name="And I see in the logs an entry with the following data:" time="0.015867"><skipped type="UndefinedStep(And I see in the logs an entry with the following data:)"/></testcase><testcase classname="Logging Mechanism : Log the unica correlator received" name="And unica_correlator example_of_correlator_32_chars__ is returned in the response" time="0.017507"><skipped type="UndefinedStep(And unica_correlator example_of_correlator_32_chars__ is returned in the response)"/></testcase><testcase classname="Logging Mechanism : Log when a client makes a request with data not supported" name="Given the DB has no classes already published" time="0.016979"/><testcase classname="Logging Mechanism : Log when a client makes a request with data not supported" name="Given the user performing the operation is:" time="0.021016"/><testcase classname="Logging Mechanism : Log when a client makes a request with data not supported" name="When I send to $base_api_url/$apis_url the data UNSTRUCTURED_DATA" time="0.021037"><failure message="classes_url" type="KeyError"><![CDATA[Traceback (most recent call last):
  File "/Library/Frameworks/Python.framework/Versions/2.7/lib/python2.7/site-packages/lettuce/core.py", line 144, in __call__
    ret = self.function(self.step, *args, **kw)
  File "/Users/eag/workspace/tdaf-servicedirectory/test/acceptance/src/e2e/logs_and_alarms/logging_mechanism/steps.py", line 81, in i_send_to_url_the_data
    rest_utils.send_to_url_the_data(step, url, data)
  File "/Users/eag/workspace/tdaf-servicedirectory/test/acceptance/src/e2e/common/rest_utils.py", line 82, in send_to_url_the_data
    url = self._get_url_with_values(url_template)
  File "/Users/eag/workspace/tdaf-servicedirectory/test/acceptance/src/e2e/common/rest_utils.py", line 365, in _get_url_with_values
    classes_url=world.config["django"]["classes_url"],
KeyError: 'classes_url'
]]></failure></testcase><testcase classname="Logging Mechanism : Log when a client makes a request with data not supported" name="Then the format of the logs is correct" time="0.020531"><skipped type="UndefinedStep(Then the format of the logs is correct)"/></testcase><testcase classname="Logging Mechanism : Log when a client makes a request with data not supported" name="And I see in the logs an entry with the following data:" time="0.016906"><skipped type="UndefinedStep(And I see in the logs an entry with the following data:)"/></testcase><testcase classname="Logging Mechanism : Log when a client makes a request with data not supported" name="And unica_correlator .{32,} is returned in the response" time="0.015859"><skipped type="UndefinedStep(And unica_correlator .{32,} is returned in the response)"/></testcase><testcase classname="Logging Mechanism : Log when a bound isntance has been deleted" name="Given the DB has no classes already published" time="0.01707"/><testcase classname="Logging Mechanism : Log when a bound isntance has been deleted" name="Given the user performing the operation is:" time="0.01871"/><testcase classname="Logging Mechanism : Log when a bound isntance has been deleted" name="And a class has already been published with data:" time="0.017921"><failure message="classes_url" type="KeyError"><![CDATA[Traceback (most recent call last):
  File "/Library/Frameworks/Python.framework/Versions/2.7/lib/python2.7/site-packages/lettuce/core.py", line 144, in __call__
    ret = self.function(self.step, *args, **kw)
  File "/Users/eag/workspace/tdaf-servicedirectory/test/acceptance/src/e2e/logs_and_alarms/logging_mechanism/steps.py", line 76, in a_class_has_already_been_published_with_data
    api_utils.a_class_has_already_been_published_with_data(step, 0)
  File "/Users/eag/workspace/tdaf-servicedirectory/test/acceptance/src/e2e/common/api_utils.py", line 341, in a_class_has_already_been_published_with_data
    rest_utils.send_to_url_the_data(step, url_template, world.old_capability)
  File "/Users/eag/workspace/tdaf-servicedirectory/test/acceptance/src/e2e/common/rest_utils.py", line 82, in send_to_url_the_data
    url = self._get_url_with_values(url_template)
  File "/Users/eag/workspace/tdaf-servicedirectory/test/acceptance/src/e2e/common/rest_utils.py", line 365, in _get_url_with_values
    classes_url=world.config["django"]["classes_url"],
KeyError: 'classes_url'
]]></failure></testcase><testcase classname="Logging Mechanism : Log when a bound isntance has been deleted" name="And an instance has already been published with data:" time="0.017354"><skipped type="UndefinedStep(And an instance has already been published with data:)"/></testcase><testcase classname="Logging Mechanism : Log when a bound isntance has been deleted" name="And the following bindings rules are available:" time="0.018046"><skipped type="UndefinedStep(And the following bindings rules are available:)"/></testcase><testcase classname="Logging Mechanism : Log when a bound isntance has been deleted" name="And the previous bindings are pusblished for the context:" time="0.018326"><skipped type="UndefinedStep(And the previous bindings are pusblished for the context:)"/></testcase><testcase classname="Logging Mechanism : Log when a bound isntance has been deleted" name="And the instance published in position 0 has been deleted" time="0.01855"><skipped type="UndefinedStep(And the instance published in position 0 has been deleted)"/></testcase><testcase classname="Logging Mechanism : Log when a bound isntance has been deleted" name="When I request the resource $base_api_url/$bind_instances_url with parameters:" time="0.01709"><skipped type="UndefinedStep(When I request the resource $base_api_url/$bind_instances_url with parameters:)"/></testcase><testcase classname="Logging Mechanism : Log when a bound isntance has been deleted" name="Then the format of the logs is correct" time="0.016048"><skipped type="UndefinedStep(Then the format of the logs is correct)"/></testcase><testcase classname="Logging Mechanism : Log when a bound isntance has been deleted" name="And I see in the logs an entry with the following data:" time="0.016092"><skipped type="UndefinedStep(And I see in the logs an entry with the following data:)"/></testcase><testcase classname="Logging Mechanism : Log when a bound isntance has been deleted" name="And unica_correlator .{32,} is returned in the response" time="0.020138"><skipped type="UndefinedStep(And unica_correlator .{32,} is returned in the response)"/></testcase><testcase classname="Logging Mechanism : Log when the initial connection to the DB cannot be established" name="Given the DB has stopped working" time="0.017823"><failure message="The Mongo DB is not down" type="AssertionError"><![CDATA[Traceback (most recent call last):
  File "/Library/Frameworks/Python.framework/Versions/2.7/lib/python2.7/site-packages/lettuce/core.py", line 144, in __call__
    ret = self.function(self.step, *args, **kw)
  File "/Users/eag/workspace/tdaf-servicedirectory/test/acceptance/src/e2e/logs_and_alarms/logging_mechanism/steps.py", line 36, in the_db_has_stopped_working
    mongo_utils.the_db_has_stopped_working(step)
  File "/Users/eag/workspace/tdaf-servicedirectory/test/acceptance/src/e2e/common/mongo_utils.py", line 40, in the_db_has_stopped_working
    assert False, "The Mongo DB is not down"
AssertionError: The Mongo DB is not down
]]></failure></testcase><testcase classname="Logging Mechanism : Log when the initial connection to the DB cannot be established" name="Given the user performing the operation is:" time="0.020582"><skipped type="UndefinedStep(Given the user performing the operation is:)"/></testcase><testcase classname="Logging Mechanism : Log when the initial connection to the DB cannot be established" name="When I restart the Service Directory" time="0.020859"><skipped type="UndefinedStep(When I restart the Service Directory)"/></testcase><testcase classname="Logging Mechanism : Log when the initial connection to the DB cannot be established" name="And I send to $base_api_url/$apis_url the class data:" time="0.015961"><skipped type="UndefinedStep(And I send to $base_api_url/$apis_url the class data:)"/></testcase><testcase classname="Logging Mechanism : Log when the initial connection to the DB cannot be established" name="Then the format of the logs is correct" time="0.016338"><skipped type="UndefinedStep(Then the format of the logs is correct)"/></testcase><testcase classname="Logging Mechanism : Log when the initial connection to the DB cannot be established" name="And I see in the logs an entry with the following data:" time="0.020108"><skipped type="UndefinedStep(And I see in the logs an entry with the following data:)"/></testcase><testcase classname="Logging Mechanism : Log when the initial connection to the DB cannot be established" name="And unica_correlator .{32,} is returned in the response" time="0.021641"><skipped type="UndefinedStep(And unica_correlator .{32,} is returned in the response)"/></testcase><testcase classname="Logging Mechanism : Log when a request to the DB fails" name="Given the user performing the operation is:" time="0.016994"/><testcase classname="Logging Mechanism : Log when a request to the DB fails" name="Given a class has already been published with data:" time="0.02342"><failure message="classes_url" type="KeyError"><![CDATA[Traceback (most recent call last):
  File "/Library/Frameworks/Python.framework/Versions/2.7/lib/python2.7/site-packages/lettuce/core.py", line 144, in __call__
    ret = self.function(self.step, *args, **kw)
  File "/Users/eag/workspace/tdaf-servicedirectory/test/acceptance/src/e2e/logs_and_alarms/logging_mechanism/steps.py", line 76, in a_class_has_already_been_published_with_data
    api_utils.a_class_has_already_been_published_with_data(step, 0)
  File "/Users/eag/workspace/tdaf-servicedirectory/test/acceptance/src/e2e/common/api_utils.py", line 341, in a_class_has_already_been_published_with_data
    rest_utils.send_to_url_the_data(step, url_template, world.old_capability)
  File "/Users/eag/workspace/tdaf-servicedirectory/test/acceptance/src/e2e/common/rest_utils.py", line 82, in send_to_url_the_data
    url = self._get_url_with_values(url_template)
  File "/Users/eag/workspace/tdaf-servicedirectory/test/acceptance/src/e2e/common/rest_utils.py", line 365, in _get_url_with_values
    classes_url=world.config["django"]["classes_url"],
KeyError: 'classes_url'
]]></failure></testcase><testcase classname="Logging Mechanism : Log when a request to the DB fails" name="Given the DB has stopped working" time="0.016622"><skipped type="UndefinedStep(Given the DB has stopped working)"/></testcase><testcase classname="Logging Mechanism : Log when a request to the DB fails" name="When I send to $base_api_url/$apis_url the class data:" time="0.015699"><skipped type="UndefinedStep(When I send to $base_api_url/$apis_url the class data:)"/></testcase><testcase classname="Logging Mechanism : Log when a request to the DB fails" name="Then the format of the logs is correct" time="0.019199"><skipped type="UndefinedStep(Then the format of the logs is correct)"/></testcase><testcase classname="Logging Mechanism : Log when a request to the DB fails" name="And I see in the logs an entry with the following data:" time="0.015845"><skipped type="UndefinedStep(And I see in the logs an entry with the following data:)"/></testcase><testcase classname="Logging Mechanism : Log when a request to the DB fails" name="And I see in the logs an entry with the following data:" time="0.016854"><skipped type="UndefinedStep(And I see in the logs an entry with the following data:)"/></testcase><testcase classname="Logging Mechanism : Log when a request to the DB fails" name="And I see in the logs an entry with the following data:" time="0.017357"><skipped type="UndefinedStep(And I see in the logs an entry with the following data:)"/></testcase><testcase classname="Logging Mechanism : Log when a request to the DB fails" name="And unica_correlator .{32,} is returned in the response" time="0.015727"><skipped type="UndefinedStep(And unica_correlator .{32,} is returned in the response)"/></testcase><testcase classname="Logging Mechanism : Log when a client makes a request to an nonexisting resource (Django exception)" name="Given the DB has no classes already published" time="0.021424"/><testcase classname="Logging Mechanism : Log when a client makes a request to an nonexisting resource (Django exception)" name="Given the user performing the operation is:" time="0.016559"/><testcase classname="Logging Mechanism : Log when a client makes a request to an nonexisting resource (Django exception)" name="When I send to $base_api_url/$classes_url/wrong_path the class data:" time="0.018158"><failure message="classes_url" type="KeyError"><![CDATA[Traceback (most recent call last):
  File "/Library/Frameworks/Python.framework/Versions/2.7/lib/python2.7/site-packages/lettuce/core.py", line 144, in __call__
    ret = self.function(self.step, *args, **kw)
  File "/Users/eag/workspace/tdaf-servicedirectory/test/acceptance/src/e2e/logs_and_alarms/logging_mechanism/steps.py", line 86, in i_send_to_url_the_class_data
    api_utils.send_to_url_the_class_data(step, url, 0, {})
  File "/Users/eag/workspace/tdaf-servicedirectory/test/acceptance/src/e2e/common/api_utils.py", line 168, in send_to_url_the_class_data
    rest_utils.send_to_url_the_data(step, url, world.published_capability, header)
  File "/Users/eag/workspace/tdaf-servicedirectory/test/acceptance/src/e2e/common/rest_utils.py", line 82, in send_to_url_the_data
    url = self._get_url_with_values(url_template)
  File "/Users/eag/workspace/tdaf-servicedirectory/test/acceptance/src/e2e/common/rest_utils.py", line 365, in _get_url_with_values
    classes_url=world.config["django"]["classes_url"],
KeyError: 'classes_url'
]]></failure></testcase><testcase classname="Logging Mechanism : Log when a client makes a request to an nonexisting resource (Django exception)" name="Then the format of the logs is correct" time="0.019249"><skipped type="UndefinedStep(Then the format of the logs is correct)"/></testcase><testcase classname="Logging Mechanism : Log when a client makes a request to an nonexisting resource (Django exception)" name="And I see in the logs an entry with the following data:" time="0.016998"><skipped type="UndefinedStep(And I see in the logs an entry with the following data:)"/></testcase><testcase classname="Logging Mechanism : Log when a client makes a request to an nonexisting resource (Django exception)" name="And unica_correlator .{32,} is returned in the response" time="0.017424"><skipped type="UndefinedStep(And unica_correlator .{32,} is returned in the response)"/></testcase><testcase classname="Logging Mechanism : Log when a client makes a request to an nonexisting resource (SD exception)" name="Given the DB has no classes already published" time="0.016706"/><testcase classname="Logging Mechanism : Log when a client makes a request to an nonexisting resource (SD exception)" name="Given the user performing the operation is:" time="0.018008"/><testcase classname="Logging Mechanism : Log when a client makes a request to an nonexisting resource (SD exception)" name="Given a class has already been published with data:" time="0.020353"><failure message="classes_url" type="KeyError"><![CDATA[Traceback (most recent call last):
  File "/Library/Frameworks/Python.framework/Versions/2.7/lib/python2.7/site-packages/lettuce/core.py", line 144, in __call__
    ret = self.function(self.step, *args, **kw)
  File "/Users/eag/workspace/tdaf-servicedirectory/test/acceptance/src/e2e/logs_and_alarms/logging_mechanism/steps.py", line 76, in a_class_has_already_been_published_with_data
    api_utils.a_class_has_already_been_published_with_data(step, 0)
  File "/Users/eag/workspace/tdaf-servicedirectory/test/acceptance/src/e2e/common/api_utils.py", line 341, in a_class_has_already_been_published_with_data
    rest_utils.send_to_url_the_data(step, url_template, world.old_capability)
  File "/Users/eag/workspace/tdaf-servicedirectory/test/acceptance/src/e2e/common/rest_utils.py", line 82, in send_to_url_the_data
    url = self._get_url_with_values(url_template)
  File "/Users/eag/workspace/tdaf-servicedirectory/test/acceptance/src/e2e/common/rest_utils.py", line 365, in _get_url_with_values
    classes_url=world.config["django"]["classes_url"],
KeyError: 'classes_url'
]]></failure></testcase><testcase classname="Logging Mechanism : Log when a client makes a request to an nonexisting resource (SD exception)" name="When I send to $base_api_url/$apis_url/Non_existing_Class/$instances_url the instance data:" time="0.015646"><skipped type="UndefinedStep(When I send to $base_api_url/$apis_url/Non_existing_Class/$instances_url the instance data:)"/></testcase><testcase classname="Logging Mechanism : Log when a client makes a request to an nonexisting resource (SD exception)" name="Then the format of the logs is correct" time="0.015838"><skipped type="UndefinedStep(Then the format of the logs is correct)"/></testcase><testcase classname="Logging Mechanism : Log when a client makes a request to an nonexisting resource (SD exception)" name="And I see in the logs an entry with the following data:" time="0.016363"><skipped type="UndefinedStep(And I see in the logs an entry with the following data:)"/></testcase><testcase classname="Logging Mechanism : Log when a client makes a request to an nonexisting resource (SD exception)" name="And unica_correlator .{32,} is returned in the response" time="0.016063"><skipped type="UndefinedStep(And unica_correlator .{32,} is returned in the response)"/></testcase><testcase classname="Logging Mechanism : Log when a a request is sent with a bad parameter and other options are presented" name="Given the user performing the operation is:" time="0.017609"/><testcase classname="Logging Mechanism : Log when a a request is sent with a bad parameter and other options are presented" name="Given a class has already been published with data:" time="0.018331"><failure message="classes_url" type="KeyError"><![CDATA[Traceback (most recent call last):
  File "/Library/Frameworks/Python.framework/Versions/2.7/lib/python2.7/site-packages/lettuce/core.py", line 144, in __call__
    ret = self.function(self.step, *args, **kw)
  File "/Users/eag/workspace/tdaf-servicedirectory/test/acceptance/src/e2e/logs_and_alarms/logging_mechanism/steps.py", line 76, in a_class_has_already_been_published_with_data
    api_utils.a_class_has_already_been_published_with_data(step, 0)
  File "/Users/eag/workspace/tdaf-servicedirectory/test/acceptance/src/e2e/common/api_utils.py", line 341, in a_class_has_already_been_published_with_data
    rest_utils.send_to_url_the_data(step, url_template, world.old_capability)
  File "/Users/eag/workspace/tdaf-servicedirectory/test/acceptance/src/e2e/common/rest_utils.py", line 82, in send_to_url_the_data
    url = self._get_url_with_values(url_template)
  File "/Users/eag/workspace/tdaf-servicedirectory/test/acceptance/src/e2e/common/rest_utils.py", line 365, in _get_url_with_values
    classes_url=world.config["django"]["classes_url"],
KeyError: 'classes_url'
]]></failure></testcase><testcase classname="Logging Mechanism : Log when a a request is sent with a bad parameter and other options are presented" name="When I send to $base_api_url/$apis_url the class data:" time="0.015741"><skipped type="UndefinedStep(When I send to $base_api_url/$apis_url the class data:)"/></testcase><testcase classname="Logging Mechanism : Log when a a request is sent with a bad parameter and other options are presented" name="Then the format of the logs is correct" time="0.019683"><skipped type="UndefinedStep(Then the format of the logs is correct)"/></testcase><testcase classname="Logging Mechanism : Log when a a request is sent with a bad parameter and other options are presented" name="And I see in the logs an entry with the following data:" time="0.016231"><skipped type="UndefinedStep(And I see in the logs an entry with the following data:)"/></testcase><testcase classname="Logging Mechanism : Log when a a request is sent with a bad parameter and other options are presented" name="And I see in the logs an entry with the following data:" time="0.017101"><skipped type="UndefinedStep(And I see in the logs an entry with the following data:)"/></testcase><testcase classname="Logging Mechanism : Log when a a request is sent with a bad parameter and other options are presented" name="And unica_correlator .{32,} is returned in the response" time="0.021956"><skipped type="UndefinedStep(And unica_correlator .{32,} is returned in the response)"/></testcase><testcase classname="Logging Mechanism : Log when a client makes a request with invalid data" name="Given the DB has no classes already published" time="0.018531"/><testcase classname="Logging Mechanism : Log when a client makes a request with invalid data" name="Given the user performing the operation is:" time="0.025099"/><testcase classname="Logging Mechanism : Log when a client makes a request with invalid data" name="Given a class has already been published with data:" time="0.019773"><failure message="classes_url" type="KeyError"><![CDATA[Traceback (most recent call last):
  File "/Library/Frameworks/Python.framework/Versions/2.7/lib/python2.7/site-packages/lettuce/core.py", line 144, in __call__
    ret = self.function(self.step, *args, **kw)
  File "/Users/eag/workspace/tdaf-servicedirectory/test/acceptance/src/e2e/logs_and_alarms/logging_mechanism/steps.py", line 76, in a_class_has_already_been_published_with_data
    api_utils.a_class_has_already_been_published_with_data(step, 0)
  File "/Users/eag/workspace/tdaf-servicedirectory/test/acceptance/src/e2e/common/api_utils.py", line 341, in a_class_has_already_been_published_with_data
    rest_utils.send_to_url_the_data(step, url_template, world.old_capability)
  File "/Users/eag/workspace/tdaf-servicedirectory/test/acceptance/src/e2e/common/rest_utils.py", line 82, in send_to_url_the_data
    url = self._get_url_with_values(url_template)
  File "/Users/eag/workspace/tdaf-servicedirectory/test/acceptance/src/e2e/common/rest_utils.py", line 365, in _get_url_with_values
    classes_url=world.config["django"]["classes_url"],
KeyError: 'classes_url'
]]></failure></testcase><testcase classname="Logging Mechanism : Log when a client makes a request with invalid data" name="When I send to $base_api_url/$apis_url/$api_name/$instances_url the instance data:" time="0.016662"><skipped type="UndefinedStep(When I send to $base_api_url/$apis_url/$api_name/$instances_url the instance data:)"/></testcase><testcase classname="Logging Mechanism : Log when a client makes a request with invalid data" name="Then the format of the logs is correct" time="0.016395"><skipped type="UndefinedStep(Then the format of the logs is correct)"/></testcase><testcase classname="Logging Mechanism : Log when a client makes a request with invalid data" name="And I see in the logs an entry with the following data:" time="0.016835"><skipped type="UndefinedStep(And I see in the logs an entry with the following data:)"/></testcase><testcase classname="Logging Mechanism : Log when a client makes a request with invalid data" name="And unica_correlator .{32,} is returned in the response" time="0.01549"><skipped type="UndefinedStep(And unica_correlator .{32,} is returned in the response)"/></testcase><testcase classname="Logging Mechanism : Log when you have invalid credentials" name="Given the DB has no classes already published" time="0.016112"/><testcase classname="Logging Mechanism : Log when you have invalid credentials" name="Given the user performing the operation is:" time="0.016304"/><testcase classname="Logging Mechanism : Log when you have invalid credentials" name="When I send to $base_api_url/$apis_url the class data:" time="0.016535"><failure message="classes_url" type="KeyError"><![CDATA[Traceback (most recent call last):
  File "/Library/Frameworks/Python.framework/Versions/2.7/lib/python2.7/site-packages/lettuce/core.py", line 144, in __call__
    ret = self.function(self.step, *args, **kw)
  File "/Users/eag/workspace/tdaf-servicedirectory/test/acceptance/src/e2e/logs_and_alarms/logging_mechanism/steps.py", line 86, in i_send_to_url_the_class_data
    api_utils.send_to_url_the_class_data(step, url, 0, {})
  File "/Users/eag/workspace/tdaf-servicedirectory/test/acceptance/src/e2e/common/api_utils.py", line 168, in send_to_url_the_class_data
    rest_utils.send_to_url_the_data(step, url, world.published_capability, header)
  File "/Users/eag/workspace/tdaf-servicedirectory/test/acceptance/src/e2e/common/rest_utils.py", line 82, in send_to_url_the_data
    url = self._get_url_with_values(url_template)
  File "/Users/eag/workspace/tdaf-servicedirectory/test/acceptance/src/e2e/common/rest_utils.py", line 365, in _get_url_with_values
    classes_url=world.config["django"]["classes_url"],
KeyError: 'classes_url'
]]></failure></testcase><testcase classname="Logging Mechanism : Log when you have invalid credentials" name="Then the format of the logs is correct" time="0.016551"><skipped type="UndefinedStep(Then the format of the logs is correct)"/></testcase><testcase classname="Logging Mechanism : Log when you have invalid credentials" name="And I see in the logs an entry with the following data:" time="0.016068"><skipped type="UndefinedStep(And I see in the logs an entry with the following data:)"/></testcase><testcase classname="Logging Mechanism : Log when you have invalid credentials" name="And unica_correlator .{32,} is returned in the response" time="0.015966"><skipped type="UndefinedStep(And unica_correlator .{32,} is returned in the response)"/></testcase><testcase classname="Logging Mechanism : Log when user has no privileges to access resource" name="Given the DB has no classes already published" time="0.01635"/><testcase classname="Logging Mechanism : Log when user has no privileges to access resource" name="Given the user performing the operation is:" time="0.020293"/><testcase classname="Logging Mechanism : Log when user has no privileges to access resource" name="Given a user has already been created with data:" time="0.01705"><failure message="classes_url" type="KeyError"><![CDATA[Traceback (most recent call last):
  File "/Library/Frameworks/Python.framework/Versions/2.7/lib/python2.7/site-packages/lettuce/core.py", line 144, in __call__
    ret = self.function(self.step, *args, **kw)
  File "/Users/eag/workspace/tdaf-servicedirectory/test/acceptance/src/e2e/logs_and_alarms/logging_mechanism/steps.py", line 138, in a_user_has_already_been_created_with_data
    i_send_to_url_the_user_data(step, "$base_api_url/$users_url", 0)
  File "/Users/eag/workspace/tdaf-servicedirectory/test/acceptance/src/e2e/logs_and_alarms/logging_mechanism/steps.py", line 143, in i_send_to_url_the_user_data
    api_utils.send_to_url_the_user_data(step, url, user_data_index)
  File "/Users/eag/workspace/tdaf-servicedirectory/test/acceptance/src/e2e/common/api_utils.py", line 268, in send_to_url_the_user_data
    rest_utils.send_to_url_the_data(step, url, step.hashes[int(user_index)])
  File "/Users/eag/workspace/tdaf-servicedirectory/test/acceptance/src/e2e/common/rest_utils.py", line 82, in send_to_url_the_data
    url = self._get_url_with_values(url_template)
  File "/Users/eag/workspace/tdaf-servicedirectory/test/acceptance/src/e2e/common/rest_utils.py", line 365, in _get_url_with_values
    classes_url=world.config["django"]["classes_url"],
KeyError: 'classes_url'
]]></failure></testcase><testcase classname="Logging Mechanism : Log when user has no privileges to access resource" name="Given the user performing the operation is:" time="0.016914"><skipped type="UndefinedStep(Given the user performing the operation is:)"/></testcase><testcase classname="Logging Mechanism : Log when user has no privileges to access resource" name="When I request a resource $base_api_url/$users_url" time="0.019083"><skipped type="UndefinedStep(When I request a resource $base_api_url/$users_url)"/></testcase><testcase classname="Logging Mechanism : Log when user has no privileges to access resource" name="Then the format of the logs is correct" time="0.016798"><skipped type="UndefinedStep(Then the format of the logs is correct)"/></testcase><testcase classname="Logging Mechanism : Log when user has no privileges to access resource" name="And I see in the logs an entry with the following data:" time="0.016402"><skipped type="UndefinedStep(And I see in the logs an entry with the following data:)"/></testcase><testcase classname="Logging Mechanism : Log when user has no privileges to access resource" name="And unica_correlator .{32,} is returned in the response" time="0.016758"><skipped type="UndefinedStep(And unica_correlator .{32,} is returned in the response)"/></testcase><testcase classname="Logging Mechanism : Log when operation not allowed" name="Given the DB has no classes already published" time="0.015861"/><testcase classname="Logging Mechanism : Log when operation not allowed" name="Given the user performing the operation is:" time="0.017222"/><testcase classname="Logging Mechanism : Log when operation not allowed" name="When I try to put in $base_api_url/$apis_url the class data:" time="0.020971"><failure message="classes_url" type="KeyError"><![CDATA[Traceback (most recent call last):
  File "/Library/Frameworks/Python.framework/Versions/2.7/lib/python2.7/site-packages/lettuce/core.py", line 144, in __call__
    ret = self.function(self.step, *args, **kw)
  File "/Users/eag/workspace/tdaf-servicedirectory/test/acceptance/src/e2e/logs_and_alarms/logging_mechanism/steps.py", line 154, in i_put_to_url_the_class_data
    rest_utils.put_in_url_the_data(step, url, step.hashes[0])
  File "/Users/eag/workspace/tdaf-servicedirectory/test/acceptance/src/e2e/common/rest_utils.py", line 146, in put_in_url_the_data
    url = self._get_url_with_values(url_template)
  File "/Users/eag/workspace/tdaf-servicedirectory/test/acceptance/src/e2e/common/rest_utils.py", line 365, in _get_url_with_values
    classes_url=world.config["django"]["classes_url"],
KeyError: 'classes_url'
]]></failure></testcase><testcase classname="Logging Mechanism : Log when operation not allowed" name="Then the format of the logs is correct" time="0.015785"><skipped type="UndefinedStep(Then the format of the logs is correct)"/></testcase><testcase classname="Logging Mechanism : Log when operation not allowed" name="And I see in the logs an entry with the following data:" time="0.01709"><skipped type="UndefinedStep(And I see in the logs an entry with the following data:)"/></testcase><testcase classname="Logging Mechanism : Log when operation not allowed" name="And unica_correlator .{32,} is returned in the response" time="0.019446"><skipped type="UndefinedStep(And unica_correlator .{32,} is returned in the response)"/></testcase><testcase classname="Logging Mechanism : Log when the default admin credentials cannot be found in the config file" name="Given the config file does not contain the default admin credentials" time="0.016915"><failure type="IOError"><![CDATA[Traceback (most recent call last):
  File "/Library/Frameworks/Python.framework/Versions/2.7/lib/python2.7/site-packages/lettuce/core.py", line 144, in __call__
    ret = self.function(self.step, *args, **kw)
  File "/Users/eag/workspace/tdaf-servicedirectory/test/acceptance/src/e2e/logs_and_alarms/logging_mechanism/steps.py", line 56, in the_config_file_does_not_contain_the_default_admin_credentials
    sd_utils.config_file_does_not_contain_default_admin_credentials()
  File "/Users/eag/workspace/tdaf-servicedirectory/test/acceptance/src/e2e/common/sd_utils.py", line 79, in config_file_does_not_contain_default_admin_credentials
    self.back_up_config_file()
  File "/Users/eag/workspace/tdaf-servicedirectory/test/acceptance/src/e2e/common/sd_utils.py", line 146, in back_up_config_file
    shutil.copy2(common_config_file, common_config_file_backup)
  File "/Library/Frameworks/Python.framework/Versions/2.7/lib/python2.7/shutil.py", line 130, in copy2
    copyfile(src, dst)
  File "/Library/Frameworks/Python.framework/Versions/2.7/lib/python2.7/shutil.py", line 82, in copyfile
    with open(src, 'rb') as fsrc:
IOError: [Errno 2] No such file or directory: u'/opt/pdi/srvdir/servicedirectory/settings/settings/common.py'
]]></failure></testcase><testcase classname="Logging Mechanism : Log when the default admin credentials cannot be found in the config file" name="Given I restart the Service Directory" time="0.018349"><skipped type="UndefinedStep(Given I restart the Service Directory)"/></testcase><testcase classname="Logging Mechanism : Log when the default admin credentials cannot be found in the config file" name="Given the user performing the operation is:" time="0.016517"><skipped type="UndefinedStep(Given the user performing the operation is:)"/></testcase><testcase classname="Logging Mechanism : Log when the default admin credentials cannot be found in the config file" name="When I send to $base_api_url/$apis_url the class data:" time="0.015751"><skipped type="UndefinedStep(When I send to $base_api_url/$apis_url the class data:)"/></testcase><testcase classname="Logging Mechanism : Log when the default admin credentials cannot be found in the config file" name="When I send to $base_api_url/$apis_url the class data:" time="0.017914"><skipped type="UndefinedStep(When I send to $base_api_url/$apis_url the class data:)"/></testcase><testcase classname="Logging Mechanism : Log when the default admin credentials cannot be found in the config file" name="Then the format of the logs is correct" time="0.01661"><skipped type="UndefinedStep(Then the format of the logs is correct)"/></testcase><testcase classname="Logging Mechanism : Log when the default admin credentials cannot be found in the config file" name="And I see in the logs an entry with the following data:" time="0.015817"><skipped type="UndefinedStep(And I see in the logs an entry with the following data:)"/></testcase><testcase classname="Logging Mechanism : Log when the default admin credentials cannot be found in the config file" name="And unica_correlator .{32,} is returned in the response" time="0.018164"><skipped type="UndefinedStep(And unica_correlator .{32,} is returned in the response)"/></testcase><testcase classname="Logging Mechanism : Log when missing mandatory param is no included in request" name="Given the user performing the operation is:" time="0.017028"/><testcase classname="Logging Mechanism : Log when missing mandatory param is no included in request" name="When I send to $base_api_url/$apis_url the class data:" time="0.021562"><failure message="classes_url" type="KeyError"><![CDATA[Traceback (most recent call last):
  File "/Library/Frameworks/Python.framework/Versions/2.7/lib/python2.7/site-packages/lettuce/core.py", line 144, in __call__
    ret = self.function(self.step, *args, **kw)
  File "/Users/eag/workspace/tdaf-servicedirectory/test/acceptance/src/e2e/logs_and_alarms/logging_mechanism/steps.py", line 86, in i_send_to_url_the_class_data
    api_utils.send_to_url_the_class_data(step, url, 0, {})
  File "/Users/eag/workspace/tdaf-servicedirectory/test/acceptance/src/e2e/common/api_utils.py", line 168, in send_to_url_the_class_data
    rest_utils.send_to_url_the_data(step, url, world.published_capability, header)
  File "/Users/eag/workspace/tdaf-servicedirectory/test/acceptance/src/e2e/common/rest_utils.py", line 82, in send_to_url_the_data
    url = self._get_url_with_values(url_template)
  File "/Users/eag/workspace/tdaf-servicedirectory/test/acceptance/src/e2e/common/rest_utils.py", line 365, in _get_url_with_values
    classes_url=world.config["django"]["classes_url"],
KeyError: 'classes_url'
]]></failure></testcase><testcase classname="Logging Mechanism : Log when missing mandatory param is no included in request" name="Then the format of the logs is correct" time="0.016142"><skipped type="UndefinedStep(Then the format of the logs is correct)"/></testcase><testcase classname="Logging Mechanism : Log when missing mandatory param is no included in request" name="And I see in the logs an entry with the following data:" time="0.016091"><skipped type="UndefinedStep(And I see in the logs an entry with the following data:)"/></testcase><testcase classname="Logging Mechanism : Log when missing mandatory param is no included in request" name="And unica_correlator .{32,} is returned in the response" time="0.015785"><skipped type="UndefinedStep(And unica_correlator .{32,} is returned in the response)"/></testcase><testcase classname="Logging Mechanism : Log when a parameter is invalid" name="Given the user performing the operation is:" time="0.020597"/><testcase classname="Logging Mechanism : Log when a parameter is invalid" name="Given a class has already been published with data:" time="0.017643"><failure message="classes_url" type="KeyError"><![CDATA[Traceback (most recent call last):
  File "/Library/Frameworks/Python.framework/Versions/2.7/lib/python2.7/site-packages/lettuce/core.py", line 144, in __call__
    ret = self.function(self.step, *args, **kw)
  File "/Users/eag/workspace/tdaf-servicedirectory/test/acceptance/src/e2e/logs_and_alarms/logging_mechanism/steps.py", line 76, in a_class_has_already_been_published_with_data
    api_utils.a_class_has_already_been_published_with_data(step, 0)
  File "/Users/eag/workspace/tdaf-servicedirectory/test/acceptance/src/e2e/common/api_utils.py", line 341, in a_class_has_already_been_published_with_data
    rest_utils.send_to_url_the_data(step, url_template, world.old_capability)
  File "/Users/eag/workspace/tdaf-servicedirectory/test/acceptance/src/e2e/common/rest_utils.py", line 82, in send_to_url_the_data
    url = self._get_url_with_values(url_template)
  File "/Users/eag/workspace/tdaf-servicedirectory/test/acceptance/src/e2e/common/rest_utils.py", line 365, in _get_url_with_values
    classes_url=world.config["django"]["classes_url"],
KeyError: 'classes_url'
]]></failure></testcase><testcase classname="Logging Mechanism : Log when a parameter is invalid" name="When I request the resource $base_api_url/$classes_url/$api_name/$instances_url with parameters:" time="0.019745"><skipped type="UndefinedStep(When I request the resource $base_api_url/$classes_url/$api_name/$instances_url with parameters:)"/></testcase><testcase classname="Logging Mechanism : Log when a parameter is invalid" name="Then the format of the logs is correct" time="0.016282"><skipped type="UndefinedStep(Then the format of the logs is correct)"/></testcase><testcase classname="Logging Mechanism : Log when a parameter is invalid" name="And I see in the logs an entry with the following data:" time="0.016191"><skipped type="UndefinedStep(And I see in the logs an entry with the following data:)"/></testcase><testcase classname="Logging Mechanism : Log when a parameter is invalid" name="And unica_correlator .{32,} is returned in the response" time="0.015806"><skipped type="UndefinedStep(And unica_correlator .{32,} is returned in the response)"/></testcase><testcase classname="Logging Mechanism : Log when a request is done with an invalid value" name="Given the user performing the operation is:" time="0.016549"/><testcase classname="Logging Mechanism : Log when a request is done with an invalid value" name="When I send to $base_api_url/$apis_url the class data:" time="0.016646"><failure message="classes_url" type="KeyError"><![CDATA[Traceback (most recent call last):
  File "/Library/Frameworks/Python.framework/Versions/2.7/lib/python2.7/site-packages/lettuce/core.py", line 144, in __call__
    ret = self.function(self.step, *args, **kw)
  File "/Users/eag/workspace/tdaf-servicedirectory/test/acceptance/src/e2e/logs_and_alarms/logging_mechanism/steps.py", line 86, in i_send_to_url_the_class_data
    api_utils.send_to_url_the_class_data(step, url, 0, {})
  File "/Users/eag/workspace/tdaf-servicedirectory/test/acceptance/src/e2e/common/api_utils.py", line 168, in send_to_url_the_class_data
    rest_utils.send_to_url_the_data(step, url, world.published_capability, header)
  File "/Users/eag/workspace/tdaf-servicedirectory/test/acceptance/src/e2e/common/rest_utils.py", line 82, in send_to_url_the_data
    url = self._get_url_with_values(url_template)
  File "/Users/eag/workspace/tdaf-servicedirectory/test/acceptance/src/e2e/common/rest_utils.py", line 365, in _get_url_with_values
    classes_url=world.config["django"]["classes_url"],
KeyError: 'classes_url'
]]></failure></testcase><testcase classname="Logging Mechanism : Log when a request is done with an invalid value" name="Then the format of the logs is correct" time="0.015984"><skipped type="UndefinedStep(Then the format of the logs is correct)"/></testcase><testcase classname="Logging Mechanism : Log when a request is done with an invalid value" name="And I see in the logs an entry with the following data:" time="0.016791"><skipped type="UndefinedStep(And I see in the logs an entry with the following data:)"/></testcase><testcase classname="Logging Mechanism : Log when a request is done with an invalid value" name="And unica_correlator .{32,} is returned in the response" time="0.016714"><skipped type="UndefinedStep(And unica_correlator .{32,} is returned in the response)"/></testcase><testcase classname="Logging Mechanism : Log when a request with unsupported type has been performed" name="Given the user performing the operation is:" time="0.016632"/><testcase classname="Logging Mechanism : Log when a request with unsupported type has been performed" name="Given the DB has no classes already published" time="0.020479"/><testcase classname="Logging Mechanism : Log when a request with unsupported type has been performed" name="When I send to $base_api_url/$apis_url the data UNSTRUCTURED_DATA" time="0.016346"><failure message="classes_url" type="KeyError"><![CDATA[Traceback (most recent call last):
  File "/Library/Frameworks/Python.framework/Versions/2.7/lib/python2.7/site-packages/lettuce/core.py", line 144, in __call__
    ret = self.function(self.step, *args, **kw)
  File "/Users/eag/workspace/tdaf-servicedirectory/test/acceptance/src/e2e/logs_and_alarms/logging_mechanism/steps.py", line 81, in i_send_to_url_the_data
    rest_utils.send_to_url_the_data(step, url, data)
  File "/Users/eag/workspace/tdaf-servicedirectory/test/acceptance/src/e2e/common/rest_utils.py", line 82, in send_to_url_the_data
    url = self._get_url_with_values(url_template)
  File "/Users/eag/workspace/tdaf-servicedirectory/test/acceptance/src/e2e/common/rest_utils.py", line 365, in _get_url_with_values
    classes_url=world.config["django"]["classes_url"],
KeyError: 'classes_url'
]]></failure></testcase><testcase classname="Logging Mechanism : Log when a request with unsupported type has been performed" name="Then the format of the logs is correct" time="0.01592"><skipped type="UndefinedStep(Then the format of the logs is correct)"/></testcase><testcase classname="Logging Mechanism : Log when a request with unsupported type has been performed" name="And I see in the logs an entry with the following data:" time="0.01684"><skipped type="UndefinedStep(And I see in the logs an entry with the following data:)"/></testcase><testcase classname="Logging Mechanism : Log when a request with unsupported type has been performed" name="And unica_correlator .{32,} is returned in the response" time="0.015795"><skipped type="UndefinedStep(And unica_correlator .{32,} is returned in the response)"/></testcase><testcase classname="Logging Mechanism : Log when you have not supplied credentials over a resource that requires them" name="Given the DB has no classes already published" time="0.016895"/><testcase classname="Logging Mechanism : Log when you have not supplied credentials over a resource that requires them" name="Given no authentication method is provided" time="0.01604"/><testcase classname="Logging Mechanism : Log when you have not supplied credentials over a resource that requires them" name="When I send to $base_api_url/$apis_url the class data:" time="0.017326"><failure message="classes_url" type="KeyError"><![CDATA[Traceback (most recent call last):
  File "/Library/Frameworks/Python.framework/Versions/2.7/lib/python2.7/site-packages/lettuce/core.py", line 144, in __call__
    ret = self.function(self.step, *args, **kw)
  File "/Users/eag/workspace/tdaf-servicedirectory/test/acceptance/src/e2e/logs_and_alarms/logging_mechanism/steps.py", line 86, in i_send_to_url_the_class_data
    api_utils.send_to_url_the_class_data(step, url, 0, {})
  File "/Users/eag/workspace/tdaf-servicedirectory/test/acceptance/src/e2e/common/api_utils.py", line 168, in send_to_url_the_class_data
    rest_utils.send_to_url_the_data(step, url, world.published_capability, header)
  File "/Users/eag/workspace/tdaf-servicedirectory/test/acceptance/src/e2e/common/rest_utils.py", line 82, in send_to_url_the_data
    url = self._get_url_with_values(url_template)
  File "/Users/eag/workspace/tdaf-servicedirectory/test/acceptance/src/e2e/common/rest_utils.py", line 365, in _get_url_with_values
    classes_url=world.config["django"]["classes_url"],
KeyError: 'classes_url'
]]></failure></testcase><testcase classname="Logging Mechanism : Log when you have not supplied credentials over a resource that requires them" name="Then the format of the logs is correct" time="0.016532"><skipped type="UndefinedStep(Then the format of the logs is correct)"/></testcase><testcase classname="Logging Mechanism : Log when you have not supplied credentials over a resource that requires them" name="And I see in the logs an entry with the following data:" time="0.016027"><skipped type="UndefinedStep(And I see in the logs an entry with the following data:)"/></testcase><testcase classname="Logging Mechanism : Log when you have not supplied credentials over a resource that requires them" name="And unica_correlator .{32,} is returned in the response" time="0.015857"><skipped type="UndefinedStep(And unica_correlator .{32,} is returned in the response)"/></testcase><testcase classname="Logging Mechanism : Log when no default rules are defined for class" name="Given the DB has no classes already published" time="0.016498"/><testcase classname="Logging Mechanism : Log when no default rules are defined for class" name="Given the user performing the operation is:" time="0.016485"/><testcase classname="Logging Mechanism : Log when no default rules are defined for class" name="And a class has already been published with data:" time="0.016178"><failure message="classes_url" type="KeyError"><![CDATA[Traceback (most recent call last):
  File "/Library/Frameworks/Python.framework/Versions/2.7/lib/python2.7/site-packages/lettuce/core.py", line 144, in __call__
    ret = self.function(self.step, *args, **kw)
  File "/Users/eag/workspace/tdaf-servicedirectory/test/acceptance/src/e2e/logs_and_alarms/logging_mechanism/steps.py", line 76, in a_class_has_already_been_published_with_data
    api_utils.a_class_has_already_been_published_with_data(step, 0)
  File "/Users/eag/workspace/tdaf-servicedirectory/test/acceptance/src/e2e/common/api_utils.py", line 341, in a_class_has_already_been_published_with_data
    rest_utils.send_to_url_the_data(step, url_template, world.old_capability)
  File "/Users/eag/workspace/tdaf-servicedirectory/test/acceptance/src/e2e/common/rest_utils.py", line 82, in send_to_url_the_data
    url = self._get_url_with_values(url_template)
  File "/Users/eag/workspace/tdaf-servicedirectory/test/acceptance/src/e2e/common/rest_utils.py", line 365, in _get_url_with_values
    classes_url=world.config["django"]["classes_url"],
KeyError: 'classes_url'
]]></failure></testcase><testcase classname="Logging Mechanism : Log when no default rules are defined for class" name="And an instance has already been published with data:" time="0.0163"><skipped type="UndefinedStep(And an instance has already been published with data:)"/></testcase><testcase classname="Logging Mechanism : Log when no default rules are defined for class" name="And the following bindings rules are available:" time="0.0165"><skipped type="UndefinedStep(And the following bindings rules are available:)"/></testcase><testcase classname="Logging Mechanism : Log when no default rules are defined for class" name="And the previous bindings are pusblished for the context:" time="0.016027"><skipped type="UndefinedStep(And the previous bindings are pusblished for the context:)"/></testcase><testcase classname="Logging Mechanism : Log when no default rules are defined for class" name="When I request the resource $base_api_url/$bind_instances_url with parameters:" time="0.016299"><skipped type="UndefinedStep(When I request the resource $base_api_url/$bind_instances_url with parameters:)"/></testcase><testcase classname="Logging Mechanism : Log when no default rules are defined for class" name="Then the format of the logs is correct" time="0.01632"><skipped type="UndefinedStep(Then the format of the logs is correct)"/></testcase><testcase classname="Logging Mechanism : Log when no default rules are defined for class" name="And I see in the logs an entry with the following data:" time="0.016364"><skipped type="UndefinedStep(And I see in the logs an entry with the following data:)"/></testcase><testcase classname="Logging Mechanism : Log when no default rules are defined for class" name="And unica_correlator .{32,} is returned in the response" time="0.015659"><skipped type="UndefinedStep(And unica_correlator .{32,} is returned in the response)"/></testcase><testcase classname="Logging Mechanism : Log when json schemas are not found" name="Given the json schemas are missing" time="0.018708"><failure type="IOError"><![CDATA[Traceback (most recent call last):
  File "/Library/Frameworks/Python.framework/Versions/2.7/lib/python2.7/site-packages/lettuce/core.py", line 144, in __call__
    ret = self.function(self.step, *args, **kw)
  File "/Users/eag/workspace/tdaf-servicedirectory/test/acceptance/src/e2e/logs_and_alarms/logging_mechanism/steps.py", line 66, in the_json_schemas_are_missing
    sd_utils.json_schemas_are_missing()
  File "/Users/eag/workspace/tdaf-servicedirectory/test/acceptance/src/e2e/common/sd_utils.py", line 115, in json_schemas_are_missing
    self.back_up_schema_file()
  File "/Users/eag/workspace/tdaf-servicedirectory/test/acceptance/src/e2e/common/sd_utils.py", line 183, in back_up_schema_file
    shutil.copy2(schema_file, schema_file_backup)
  File "/Library/Frameworks/Python.framework/Versions/2.7/lib/python2.7/shutil.py", line 130, in copy2
    copyfile(src, dst)
  File "/Library/Frameworks/Python.framework/Versions/2.7/lib/python2.7/shutil.py", line 82, in copyfile
    with open(src, 'rb') as fsrc:
IOError: [Errno 2] No such file or directory: u'/opt/pdi/srvdir/servicedirectory/settings/schemas/class-schema.json'
]]></failure></testcase><testcase classname="Logging Mechanism : Log when json schemas are not found" name="Given I restart the Service Directory" time="0.016658"><skipped type="UndefinedStep(Given I restart the Service Directory)"/></testcase><testcase classname="Logging Mechanism : Log when json schemas are not found" name="Given the user performing the operation is:" time="0.016565"><skipped type="UndefinedStep(Given the user performing the operation is:)"/></testcase><testcase classname="Logging Mechanism : Log when json schemas are not found" name="When I send to $base_api_url/$apis_url the class data:" time="0.021251"><skipped type="UndefinedStep(When I send to $base_api_url/$apis_url the class data:)"/></testcase><testcase classname="Logging Mechanism : Log when json schemas are not found" name="Then the format of the logs is correct" time="0.015798"><skipped type="UndefinedStep(Then the format of the logs is correct)"/></testcase><testcase classname="Logging Mechanism : Log when json schemas are not found" name="And I see in the logs an entry with the following data:" time="0.016705"><skipped type="UndefinedStep(And I see in the logs an entry with the following data:)"/></testcase><testcase classname="Logging Mechanism : Log when json schemas are not found" name="And I see in the logs an entry with the following data:" time="0.017095"><skipped type="UndefinedStep(And I see in the logs an entry with the following data:)"/></testcase><testcase classname="Logging Mechanism : Log when json schemas folder is not found" name="Given the json schemas folder is missing" time="0.047728"><failure message="cannot copy tree '/opt/pdi/srvdir/servicedirectory/settings/schemas': not a directory" type="DistutilsFileError"><![CDATA[Traceback (most recent call last):
  File "/Library/Frameworks/Python.framework/Versions/2.7/lib/python2.7/site-packages/lettuce/core.py", line 144, in __call__
    ret = self.function(self.step, *args, **kw)
  File "/Users/eag/workspace/tdaf-servicedirectory/test/acceptance/src/e2e/logs_and_alarms/logging_mechanism/steps.py", line 71, in the_json_schemas_folder_is_missing
    sd_utils.json_schemas_folder_is_missing()
  File "/Users/eag/workspace/tdaf-servicedirectory/test/acceptance/src/e2e/common/sd_utils.py", line 128, in json_schemas_folder_is_missing
    self.back_up_schema_folder()
  File "/Users/eag/workspace/tdaf-servicedirectory/test/acceptance/src/e2e/common/sd_utils.py", line 220, in back_up_schema_folder
    dir_util.copy_tree(schema_folder, schema_folder_backup)
  File "/Library/Frameworks/Python.framework/Versions/2.7/lib/python2.7/distutils/dir_util.py", line 128, in copy_tree
    "cannot copy tree '%s': not a directory" % src
DistutilsFileError: cannot copy tree '/opt/pdi/srvdir/servicedirectory/settings/schemas': not a directory
]]></failure></testcase><testcase classname="Logging Mechanism : Log when json schemas folder is not found" name="Given I restart the Service Directory" time="0.017219"><skipped type="UndefinedStep(Given I restart the Service Directory)"/></testcase><testcase classname="Logging Mechanism : Log when json schemas folder is not found" name="Given the user performing the operation is:" time="0.016204"><skipped type="UndefinedStep(Given the user performing the operation is:)"/></testcase><testcase classname="Logging Mechanism : Log when json schemas folder is not found" name="When I send to $base_api_url/$apis_url the class data:" time="0.016323"><skipped type="UndefinedStep(When I send to $base_api_url/$apis_url the class data:)"/></testcase><testcase classname="Logging Mechanism : Log when json schemas folder is not found" name="Then the format of the logs is correct" time="0.016758"><skipped type="UndefinedStep(Then the format of the logs is correct)"/></testcase><testcase classname="Logging Mechanism : Log when json schemas folder is not found" name="And I see in the logs an entry with the following data:" time="0.015977"><skipped type="UndefinedStep(And I see in the logs an entry with the following data:)"/></testcase><testcase classname="Logging Mechanism : Log when json schemas folder is not found" name="And I see in the logs an entry with the following data:" time="0.016033"><skipped type="UndefinedStep(And I see in the logs an entry with the following data:)"/></testcase><testcase classname="Logging Mechanism : Log when the correlator header cannot be found in the config file" name="Given the config file does not contain the correlator header" time="0.016806"><failure type="IOError"><![CDATA[Traceback (most recent call last):
  File "/Library/Frameworks/Python.framework/Versions/2.7/lib/python2.7/site-packages/lettuce/core.py", line 144, in __call__
    ret = self.function(self.step, *args, **kw)
  File "/Users/eag/workspace/tdaf-servicedirectory/test/acceptance/src/e2e/logs_and_alarms/logging_mechanism/steps.py", line 61, in the_config_file_does_not_contain_the_correlator_header
    sd_utils.config_file_does_not_contain_the_correlator_header()
  File "/Users/eag/workspace/tdaf-servicedirectory/test/acceptance/src/e2e/common/sd_utils.py", line 96, in config_file_does_not_contain_the_correlator_header
    self.back_up_config_file()
  File "/Users/eag/workspace/tdaf-servicedirectory/test/acceptance/src/e2e/common/sd_utils.py", line 146, in back_up_config_file
    shutil.copy2(common_config_file, common_config_file_backup)
  File "/Library/Frameworks/Python.framework/Versions/2.7/lib/python2.7/shutil.py", line 130, in copy2
    copyfile(src, dst)
  File "/Library/Frameworks/Python.framework/Versions/2.7/lib/python2.7/shutil.py", line 82, in copyfile
    with open(src, 'rb') as fsrc:
IOError: [Errno 2] No such file or directory: u'/opt/pdi/srvdir/servicedirectory/settings/settings/common.py'
]]></failure></testcase><testcase classname="Logging Mechanism : Log when the correlator header cannot be found in the config file" name="Given I restart the Service Directory" time="0.01663"><skipped type="UndefinedStep(Given I restart the Service Directory)"/></testcase><testcase classname="Logging Mechanism : Log when the correlator header cannot be found in the config file" name="Given the user performing the operation is:" time="0.016509"><skipped type="UndefinedStep(Given the user performing the operation is:)"/></testcase><testcase classname="Logging Mechanism : Log when the correlator header cannot be found in the config file" name="When I send to $base_api_url/$apis_url the class data:" time="0.016029"><skipped type="UndefinedStep(When I send to $base_api_url/$apis_url the class data:)"/></testcase><testcase classname="Logging Mechanism : Log when the correlator header cannot be found in the config file" name="Then the format of the logs is correct" time="0.016051"><skipped type="UndefinedStep(Then the format of the logs is correct)"/></testcase><testcase classname="Logging Mechanism : Log when the correlator header cannot be found in the config file" name="And I see in the logs an entry with the following data:" time="0.016826"><skipped type="UndefinedStep(And I see in the logs an entry with the following data:)"/></testcase><testcase classname="Logging Mechanism : Log when a request with Json not valid is performed" name="Given the user performing the operation is:" time="0.018906"/><testcase classname="Logging Mechanism : Log when a request with Json not valid is performed" name="And a class has already been published with data:" time="0.020719"><failure message="classes_url" type="KeyError"><![CDATA[Traceback (most recent call last):
  File "/Library/Frameworks/Python.framework/Versions/2.7/lib/python2.7/site-packages/lettuce/core.py", line 144, in __call__
    ret = self.function(self.step, *args, **kw)
  File "/Users/eag/workspace/tdaf-servicedirectory/test/acceptance/src/e2e/logs_and_alarms/logging_mechanism/steps.py", line 76, in a_class_has_already_been_published_with_data
    api_utils.a_class_has_already_been_published_with_data(step, 0)
  File "/Users/eag/workspace/tdaf-servicedirectory/test/acceptance/src/e2e/common/api_utils.py", line 341, in a_class_has_already_been_published_with_data
    rest_utils.send_to_url_the_data(step, url_template, world.old_capability)
  File "/Users/eag/workspace/tdaf-servicedirectory/test/acceptance/src/e2e/common/rest_utils.py", line 82, in send_to_url_the_data
    url = self._get_url_with_values(url_template)
  File "/Users/eag/workspace/tdaf-servicedirectory/test/acceptance/src/e2e/common/rest_utils.py", line 365, in _get_url_with_values
    classes_url=world.config["django"]["classes_url"],
KeyError: 'classes_url'
]]></failure></testcase><testcase classname="Logging Mechanism : Log when a request with Json not valid is performed" name="And an instance has already been published with data:" time="0.0161"><skipped type="UndefinedStep(And an instance has already been published with data:)"/></testcase><testcase classname="Logging Mechanism : Log when a request with Json not valid is performed" name="And the following bindings rules are available:" time="0.015795"><skipped type="UndefinedStep(And the following bindings rules are available:)"/></testcase><testcase classname="Logging Mechanism : Log when a request with Json not valid is performed" name="When I send to $base_api_url/$bindings_url the rule data:" time="0.016379"><skipped type="UndefinedStep(When I send to $base_api_url/$bindings_url the rule data:)"/></testcase><testcase classname="Logging Mechanism : Log when a request with Json not valid is performed" name="Then the format of the logs is correct" time="0.01657"><skipped type="UndefinedStep(Then the format of the logs is correct)"/></testcase><testcase classname="Logging Mechanism : Log when a request with Json not valid is performed" name="And I see in the logs an entry with the following data:" time="0.015958"><skipped type="UndefinedStep(And I see in the logs an entry with the following data:)"/></testcase><testcase classname="Logging Mechanism : Log when a request with Json not valid is performed" name="And unica_correlator .{32,} is returned in the response" time="0.016259"><skipped type="UndefinedStep(And unica_correlator .{32,} is returned in the response)"/></testcase><testcase classname="Logging Mechanism : Log when validation of user can not be done with mongo" name="Given the DB has no classes already published" time="0.01596"/><testcase classname="Logging Mechanism : Log when validation of user can not be done with mongo" name="Given the user performing the operation is:" time="0.016736"/><testcase classname="Logging Mechanism : Log when validation of user can not be done with mongo" name="Given a user has already been created with data:" time="0.016725"><failure message="classes_url" type="KeyError"><![CDATA[Traceback (most recent call last):
  File "/Library/Frameworks/Python.framework/Versions/2.7/lib/python2.7/site-packages/lettuce/core.py", line 144, in __call__
    ret = self.function(self.step, *args, **kw)
  File "/Users/eag/workspace/tdaf-servicedirectory/test/acceptance/src/e2e/logs_and_alarms/logging_mechanism/steps.py", line 138, in a_user_has_already_been_created_with_data
    i_send_to_url_the_user_data(step, "$base_api_url/$users_url", 0)
  File "/Users/eag/workspace/tdaf-servicedirectory/test/acceptance/src/e2e/logs_and_alarms/logging_mechanism/steps.py", line 143, in i_send_to_url_the_user_data
    api_utils.send_to_url_the_user_data(step, url, user_data_index)
  File "/Users/eag/workspace/tdaf-servicedirectory/test/acceptance/src/e2e/common/api_utils.py", line 268, in send_to_url_the_user_data
    rest_utils.send_to_url_the_data(step, url, step.hashes[int(user_index)])
  File "/Users/eag/workspace/tdaf-servicedirectory/test/acceptance/src/e2e/common/rest_utils.py", line 82, in send_to_url_the_data
    url = self._get_url_with_values(url_template)
  File "/Users/eag/workspace/tdaf-servicedirectory/test/acceptance/src/e2e/common/rest_utils.py", line 365, in _get_url_with_values
    classes_url=world.config["django"]["classes_url"],
KeyError: 'classes_url'
]]></failure></testcase><testcase classname="Logging Mechanism : Log when validation of user can not be done with mongo" name="Given the user performing the operation is:" time="0.016195"><skipped type="UndefinedStep(Given the user performing the operation is:)"/></testcase><testcase classname="Logging Mechanism : Log when validation of user can not be done with mongo" name="Given the passwords have been deleted" time="0.016552"><skipped type="UndefinedStep(Given the passwords have been deleted)"/></testcase><testcase classname="Logging Mechanism : Log when validation of user can not be done with mongo" name="Given the user performing the operation is:" time="0.016828"><skipped type="UndefinedStep(Given the user performing the operation is:)"/></testcase><testcase classname="Logging Mechanism : Log when validation of user can not be done with mongo" name="When I send to $base_api_url/$apis_url the class data:" time="0.015962"><skipped type="UndefinedStep(When I send to $base_api_url/$apis_url the class data:)"/></testcase><testcase classname="Logging Mechanism : Log when validation of user can not be done with mongo" name="Then the format of the logs is correct" time="0.016053"><skipped type="UndefinedStep(Then the format of the logs is correct)"/></testcase><testcase classname="Logging Mechanism : Log when validation of user can not be done with mongo" name="And I see in the logs an entry with the following data:" time="0.020219"><skipped type="UndefinedStep(And I see in the logs an entry with the following data:)"/></testcase><testcase classname="Logging Mechanism : Log when validation of user can not be done with mongo" name="And I see in the logs an entry with the following data:" time="0.015777"><skipped type="UndefinedStep(And I see in the logs an entry with the following data:)"/></testcase><testcase classname="Logging Mechanism : Log when validation of user can not be done with mongo" name="And the DB has been deleted" time="0.015931"><skipped type="UndefinedStep(And the DB has been deleted)"/></testcase><testcase classname="Logging Mechanism : Log when validation of user can not be done with mongo" name="And unica_correlator .{32,} is returned in the response" time="0.016687"><skipped type="UndefinedStep(And unica_correlator .{32,} is returned in the response)"/></testcase></testsuite>